<?xml version="1.0"?>
<robot name="abot">
  <!-- Материалы -->
  <material name="Green">
    <color rgba="0.0 1.0 0.0 1.0"/>
  </material>
  <material name="Blue">
    <color rgba="0.0 0.0 1.0 1.0"/>
  </material>
  <material name="Red">
    <color rgba="1.0 0.0 0.0 1.0"/>
  </material>
  <material name="White">
    <color rgba="1.0 1.0 1.0 1.0"/>
  </material>
  <material name="Yellow">
    <color rgba="1.0 1.0 0.0 1.0"/>
  </material>

  <!-- Base Footprint Link -->
  <link name="base_footprint">
    <visual>
      <origin rpy="0 0 0" xyz="0 0 0"/>
      <geometry>
        <cylinder length="0.001" radius="0.100"/>
      </geometry>
      <material name="Blue"/>
    </visual>
  </link>

  <!-- Base Link -->
<link name="base_link">
    <inertial>
        <origin xyz="0 0 0.05" rpy="0 0 0"/>
        <mass value="5.0"/>
        <inertia ixx="0.1" ixy="0" ixz="0" 
                 iyy="0.1" iyz="0" 
                 izz="0.1"/>
    </inertial>
    <visual>
        <origin rpy="0 0 0" xyz="0 0 0"/>
        <geometry>
            <sphere radius="0.001"/>
        </geometry>
    </visual>
</link>

  <!-- Abot Base Link -->
  <link name="abot_base">
    <inertial>
      <!-- <origin rpy="0 0 0" xyz="-0.017258 -0.00044491 0.079113"/> -->
      <origin xyz="0 0 -0.05" rpy="0 0 0"/>
      <mass value="0.71798"/>
      <inertia ixx="0.00077488" ixy="-3.248E-06" ixz="-9.2329E-06" iyy="0.00075836" iyz="2.2456E-06" izz="0.0014158"/>
    </inertial>
    <visual>
      <origin rpy="0 0 0" xyz="0 0 0"/>
      <geometry>
        <mesh filename="package://abot_description/meshes/abot_base.STL"/>
      </geometry>
      <material name="White"/>
    </visual>
    <collision>
      <origin rpy="0 0 0" xyz="0 0 0"/>
      <geometry>
        <mesh filename="package://abot_description/meshes/abot_base.STL"/>
      </geometry>
    </collision>
  </link>

  <!-- Joints -->
  <joint name="base_footprint_to_base_link" type="fixed">
    <origin rpy="0 0 0" xyz="0 0 0"/>
    <parent link="base_footprint"/>
    <child link="base_link"/>
    <!-- <axis xyz="0 0 1"/> Разрешаем вращение только вокруг оси Z -->
  </joint>

  <gazebo>
  <plugin name="joint_control" filename="libgazebo_ros_joint_pose_trajectory.so">
    <topicName>cmd_vel</topicName>
    <updateRate>100.0</updateRate>
    <jointName>base_footprint_to_base_link</jointName>
    <robotNamespace>/</robotNamespace>
    <!-- Ограничиваем вращение только вокруг оси Z -->
    <constraintAxes>0 0 1</constraintAxes>
  </plugin>
</gazebo>

  <joint name="base_link_to_abot_base" type="fixed">
    <origin rpy="0 0 0" xyz="0 0 0"/>
    <parent link="base_link"/>
    <child link="abot_base"/>
  </joint>

  <!-- Left Wheel -->
  <link name="left_wheel">
    <visual>
      <origin rpy="1.5707963 0 0" xyz="0 0 0"/>
      <geometry>
        <cylinder length="0.026" radius="0.03195"/>
      </geometry>
      <material name="Green"/>
    </visual>
    <collision>
      <origin rpy="1.5707963 0 0" xyz="0 0 0"/>
      <geometry>
        <cylinder length="0.026" radius="0.03195"/>
      </geometry>
    </collision>
    <inertial>
      <mass value="200000.050464"/>
      <inertia ixx="2.0701E-05" ixy="0" ixz="0" iyy="3.5827E-05" iyz="0" izz="2.0701E-05"/>
      <origin rpy="0 0 0" xyz="0 0 0"/>
    </inertial>
  </link>

  <!-- Right Wheel -->
  <link name="right_wheel">
    <visual>
      <origin rpy="1.5707963 0 0" xyz="0 0 0"/>
      <geometry>
        <cylinder length="0.026" radius="0.03195"/>
      </geometry>
      <material name="Green"/>
    </visual>
    <collision>
      <origin rpy="1.5707963 0 0" xyz="0 0 0"/>
      <geometry>
        <cylinder length="0.026" radius="0.03195"/>
      </geometry>
    </collision>
    <inertial>
      <mass value="200000.050464"/>
      <inertia ixx="2.0701E-05" ixy="0" ixz="0" iyy="3.5827E-05" iyz="0" izz="2.0701E-05"/>
      <origin rpy="0 0 0" xyz="0 0 0"/>
    </inertial>
  </link>
	<!-- caster_wheel -->
	<link name="abot_caster_wheel">
		<inertial>
			<origin xyz="0 1.6073E-19 0" rpy="0 0 0"/>
			<mass value="10.011207"/>
			<inertia ixx="2.1965E-07" ixy="-1.5533E-55" ixz="-1.9776E-56" iyy="2.1965E-07" iyz="-2.2674E-40" izz="2.1965E-07"/>
		</inertial>
		<visual>
			<origin xyz="0 0 0" rpy="0 0 0" />
			<geometry>
				<mesh filename="package://abot_description/meshes/abot_caster_wheel.STL" />
			</geometry>
			<material name="Green" />
		</visual>
		<collision>
			<origin xyz="0 0 0" rpy="0 0 0" />
			<geometry>
				<mesh filename="package://abot_description/meshes/abot_caster_wheel.STL" />
			</geometry>
		</collision>
	</link>
	<joint name="caster_wheel_to_base" type="planar">
		<origin xyz="-0.078 0 -0.011" rpy="0 0 3.14" />
		<parent link="abot_base" />
		<child link="abot_caster_wheel" />
		<axis xyz="1 1 0" />
	</joint>

  <!-- Wheel Joints -->
  <joint name="left_wheel_joint" type="continuous">
    <origin rpy="0 0 0" xyz="0 0.068 0.0145"/>
    <parent link="abot_base"/>
    <child link="left_wheel"/>
    <axis xyz="0 1 0"/>
  </joint>

  <joint name="right_wheel_joint" type="continuous">
    <origin rpy="0 0 0" xyz="0 -0.068 0.0145"/>
    <parent link="abot_base"/>
    <child link="right_wheel"/>
    <axis xyz="0 1 0"/>
  </joint>

  <!-- Caster Wheel -->
<link name="caster_wheel">
    <visual>
        <origin rpy="0 0 0" xyz="0 0 0"/>
        <geometry>
            <sphere radius="0.004"/>
        </geometry>
        <material name="Black"/>
    </visual>
    <collision>
        <origin rpy="0 0 0" xyz="0 0 0"/>
        <geometry>
            <sphere radius="0.004"/>
        </geometry>
    </collision>
    <inertial>
        <mass value="0.1"/>
        <!-- <inertia ixx="0.00001" ixy="0" ixz="0" 
                 iyy="0.00001" iyz="0" 
                 izz="0.00001"/> -->
        <origin rpy="0 0 0" xyz="0 0 0"/>
    </inertial>
</link>

  <joint name="caster_wheel_joint" type="planar">
    <origin rpy="0 0 0" xyz="-0.078 0 -0"/>
    <parent link="abot_base"/>
    <child link="caster_wheel"/>
    <axis xyz="1 1 0"/>
  </joint>


<gazebo reference="left_wheel">
    <mu1>1.0</mu1>
    <mu2>1.0</mu2>
    <kp>1000000.0</kp>
    <kd>100.0</kd>
    <minDepth>0.01</minDepth>
    <maxVel>0.1</maxVel>
    <fdir1>1 0 0</fdir1>
</gazebo>

<gazebo reference="right_wheel">
    <mu1>1.0</mu1>
    <mu2>1.0</mu2>
    <kp>1000000.0</kp>
    <kd>100.0</kd>
    <minDepth>0.01</minDepth>
    <maxVel>0.1</maxVel>
    <fdir1>1 0 0</fdir1>
</gazebo>

<gazebo reference="caster_wheel">
    <mu1>0.1</mu1>
    <mu2>0.1</mu2>
    <kp>1000000.0</kp>
    <kd>100.0</kd>
    <minDepth>0.01</minDepth>
    <maxVel>0.1</maxVel>
    <fdir1>1 0 0</fdir1>
</gazebo>

  <!-- Lidar -->
  <link name="abot_lidar">
    <visual>
      <origin rpy="0 0 0" xyz="0 0 0"/>
      <geometry>
        <mesh filename="package://abot_description/meshes/abot_lidar.STL"/>
      </geometry>
      <material name="Yellow"/>
    </visual>
    <collision>
      <origin rpy="0 0 0" xyz="0 0 0"/>
      <geometry>
        <mesh filename="package://abot_description/meshes/abot_lidar.STL"/>
      </geometry>
    </collision>
  </link>

  <joint name="lidar_joint" type="fixed">
    <origin rpy="0 0 3.14159" xyz="-0.01 0 0.1849"/>
    <parent link="abot_base"/>
    <child link="abot_lidar"/>
  </joint>

  <!-- Camera -->
  <link name="camera">
    <material name="red">
        <color rgba="1 0 0 1"/>
    </material>
    <visual>
      <geometry>
        <box size="0.02 0.02 0.02"/>
      </geometry>
      <material name="Blue"/>
    </visual>
    <collision>
      <geometry>
        <box size="0.02 0.02 0.02"/>
      </geometry>
    </collision>
  </link>

  <joint name="camera_joint" type="fixed">
    <origin rpy="0 0 -3.14159" xyz="-0.085 0 0.1"/>
    <parent link="base_link"/>
    <child link="camera"/>
  </joint>

  <!-- Gazebo Plugins -->
<gazebo>
  <plugin name="force_based_move" filename="libgazebo_ros_force_based_move.so">
    <commandTopic>cmd_vel</commandTopic>
    <odometryTopic>odom</odometryTopic>
    <odometryFrame>odom</odometryFrame>
    <odometryRate>50.0</odometryRate>
    <robotBaseFrame>base_footprint</robotBaseFrame>
    <forceName>force_based_move</forceName>
    <yaw_velocity_p_gain>1</yaw_velocity_p_gain>
    <x_velocity_p_gain>1</x_velocity_p_gain>
    <y_velocity_p_gain>1</y_velocity_p_gain>
  </plugin>
</gazebo>
<gazebo>
  <plugin name="planar_move" filename="libgazebo_ros_planar_move.so">
    <commandTopic>cmd_vel</commandTopic>
    <odometryTopic>odom</odometryTopic>
    <odometryFrame>odom</odometryFrame>
    <odometryRate>20.0</odometryRate>
    <robotBaseFrame>base_footprint</robotBaseFrame>
    <publishOdometryTf>true</publishOdometryTf>
    <!-- Запрещаем вращение вокруг X и Y -->
    <lockRotationXY>true</lockRotationXY>
  </plugin>
</gazebo>

  <!-- Camera Gazebo Plugin -->
  <gazebo reference="camera">
    <sensor name="camera" type="camera">
      <update_rate>30.0</update_rate>
      <camera name="head">
        <horizontal_fov>2.0944</horizontal_fov>
        <vertical_fov>1.5708</vertical_fov>
        <image>
          <width>1280</width>
          <height>720</height>
          <format>R8G8B8</format>
        </image>
        <clip>
          <near>0.02</near>
          <far>300</far>
        </clip>
        <noise>
          <type>gaussian</type>
          <mean>0.0</mean>
          <stddev>0.007</stddev>
        </noise>
      </camera>
      <plugin filename="libgazebo_ros_camera.so" name="camera_controller">
        <alwaysOn>true</alwaysOn>
        <updateRate>0.0</updateRate>
        <cameraName>/mybot/camera</cameraName>
        <imageTopicName>image_raw</imageTopicName>
        <cameraInfoTopicName>camera_info</cameraInfoTopicName>
        <frameName>camera</frameName>
        <hackBaseline>0.07</hackBaseline>
        <distortionK1>0.0</distortionK1>
        <distortionK2>0.0</distortionK2>
        <distortionK3>0.0</distortionK3>
        <distortionT1>0.0</distortionT1>
        <distortionT2>0.0</distortionT2>
      </plugin>
    </sensor>
  </gazebo>
  <gazebo reference="abot_lidar">
    <sensor type="ray" name="rplidar_a1">
      <pose>0 0 0 0 0 0</pose>
      <visualize>false</visualize>
      <update_rate>5.5</update_rate>
      <ray>
        <scan>
          <horizontal>
            <samples>360</samples>
            <resolution>1</resolution>
            <min_angle>-3.14159</min_angle>
            <max_angle>3.14159</max_angle>
          </horizontal>
        </scan>
        <range>
          <min>0.15</min>
          <max>12.0</max>
          <resolution>0.01</resolution>
        </range>
        <noise>
          <type>gaussian</type>
          <mean>0.0</mean>
          <stddev>0.01</stddev>
        </noise>
      </ray>
      <plugin name="gazebo_ros_head_rplidar_controller" filename="libgazebo_ros_laser.so">
        <topicName>/scan</topicName>
        <frameName>abot_lidar</frameName>
      </plugin>
    </sensor>
</gazebo>

</robot>